Workbook

Sheet 작성 매뉴얼
A1: 기능 설명
W6: 해당 버튼을 눌러 M4000, M4500번지로 이동
W17: 6K, 8K / Chamber / PACC
W18: 순서로 양식이 있습니다.
C35: 6K, 8K 설계 시 버튼을 눌러 전체 T번지 영역 선택하여 복사 | J35: Chamber 설계 시 버튼을 눌러 전체 T번지 영역 선택하여 복사 | P35: PACC 설계 시 버튼을 눌러 전체 T번지 영역 선택하여 복사
A37: 작성 순서
B42: 1. 전장설계팀으로부터 I/O Map을 받으면 [1. IO 작성 Map] 시트에 붙여넣기 한다.
B43: (해당영역에 I/O Comment 입력)
B66: 2. [3. M-Memory Map] 시트에서 해당 설비의 양식을 제외한 다른 설비의 양식은 제거한다.
B67: (아래 사진은 6K, 8K 설비를 할 경우 예시)
B84: 3. 상단바에 있는 [EQ] 버튼을 누르면, M4000~M4499번지에 해당하는 T영역이 선택이 됩니다.
B85: 선택영역을 복사하여 [T Matching]영역에 붙여넣기 합니다.
B110: 4. [2. T-Memory Map]에서 해당영역에 T번지를 매칭합니다.
B111: (T4000~T4699: EQ, Chamber / T4700~T4999: PACC)
B138: 5. [IO List Map]에서 Matching 검토를 합니다.
R148: 해당영역 Matching이 되어있지 않으므로 확인해야 한다.
A161: 상세 설명
B165: # M번지를 공용으로 사용하는 영역
B166: 공용으로 사용하는 영역의 경우 Title에 /로 나누어 표시했습니다.
B167: Ex)
B207: # 신규 I/O가 생겼을 경우
B208: 해당 신규 I/O가 계속 설비에 사용된다면, Spare 공간에 추가를 하고 표준 Update를 해야합니다.
B209: (일시적으로 사용할 경우 Spare 공간에 추가하여 사용하고 표준은 Update 하지않음)

Sheet 1. IO 작성 Map
E1: A접 센서 | F1: 검정
B2: B RATE | C2: 4 | E2: B접 센서 | F2: 빨강 | K2: B RATE | L2: 4 | S2: B RATE | T2: 4 | AA2: B RATE | AB2: 4
B3: INPUT | K3: OUTPUT | S3: MODE | T3: 3 | AA3: MODE | AB3: 1
S4: ANALOG INPUT | AA4: SW ON↑ | AB4: 1, 3, 5
B5: STATION No. | C5: Part No. | D5: 번호 | E5: I/O | F5: Description | G5: I/O Check | H5: 비고 | K5: STATION No. | L5: Part No. | M5: 번호 | N5: I/O | O5: Description | P5: I/O Check | Q5: 비고 | AA5: RS-232 COMM.
B6: EQ | K6: PROFILE | S6: STATION No. | T6: Part No. | U6: 번호 | V6: I/O | W6: Description | AA6: STATION No. | AB6: Part No. | AC6: 번호 | AF6: Description
B7: 1 | C7: AJ65SBTB1-32D1 | D7: 1 | E7: X1000 | F7: FRONT LEFT (FL) FIXTURE FWD | K7: 9 | L7: AJ65SBTB1-32T1 | M7: 1 | N7: Y1100 | O7: FRONT FIXTURE FWD | S7: Profile I/O Pannel
D8: 2 | E8: X1001 | F8: FRONT LEFT (FL) FIXTURE REV | M8: 2 | N8: Y1101 | O8: RIGHT FIXTURE FWD | S8: 25 | T8: AJ65VBTCU-68ADVN | U8: 1 | V8: CH1 | W8: CDA 01 | Y8: ISE20B
D9: 3 | E9: X1002 | F9: FRONT RIGHT (FR) FIXTURE FWD | M9: 3 | N9: Y1102 | O9: BACK FIXTURE FWD | U9: 2 | V9: CH2 | W9: CDA 02 | Y9: ISE20B
D10: 4 | E10: X1003 | F10: FRONT RIGHT (FR) FIXTURE REV | M10: 4 | N10: Y1103 | O10: LEFT FIXTURE FWD | U10: 3 | V10: CH3 | W10: CDA 03 | Y10: ISE20B | AA10: B RATE | AB10: 4
D11: 5 | E11: X1004 | F11: RIGHT FRONT (RF) FIXTURE FWD | M11: 5 | N11: Y1104 | O11: SPARE | U11: 4 | V11: CH4 | W11: FIXTURE 01 | Y11: ISE20B | AA11: MODE | AB11: 1
D12: 6 | E12: X1005 | F12: RIGHT FRONT (RF) FIXTURE REV | M12: 6 | N12: Y1105 | O12: SPARE | U12: 5 | V12: CH5 | W12: FIXTURE 02 | Y12: ISE20B | AA12: SW ON↑ | AB12: 1, 3, 5
D13: 7 | E13: X1006 | F13: RIGHT BACK (RB) FIXTURE FWD | M13: 7 | N13: Y1106 | O13: SAMPLE PLATE BLOWING | U13: 6 | V13: CH6 | W13: ISOLATOR 01 | Y13: ISE20B | AA13: RS-232 COMM.
D14: 8 | E14: X1007 | F14: RIGHT BACK (RB) FIXTURE REV | M14: 8 | N14: Y1107 | O14: SPARE | U14: 7 | V14: CH7 | W14: ISOLATOR 02 | Y14: ISE20B | AA14: STATION No. | AB14: Part No. | AC14: 번호 | AF14: Description
D15: 9 | E15: X1008 | F15: BACK RIGHT (BR) FIXTURE FWD | M15: 9 | N15: Y1108 | O15: SAMPLE PLATE VACUUM | U15: 8 | V15: CH8 | W15: SHUTTER | Y15: ISE20B
D16: 10 | E16: X1009 | F16: BACK RIGHT (BR) FIXTURE REV | M16: 10 | N16: Y1109 | O16: SPARE
D17: 11 | E17: X100A | F17: BACK LEFT (BL) FIXTURE FWD | M17: 11 | N17: Y110A | O17: SHUTTER OPEN | S17: B RATE | T17: 4
D18: 12 | E18: X100B | F18: BACK LEFT (BL) FIXTURE REV | M18: 12 | N18: Y110B | O18: SHUTTER CLOSE | S18: MODE | T18: 3 | AA18: B RATE | AB18: 4
D19: 13 | E19: X100C | F19: LEFT BACK (LB) FIXTURE FWD | M19: 13 | N19: Y110C | O19: SPARE | S19: ANALOG INPUT | AA19: MODE | AB19: 1
D20: 14 | E20: X100D | F20: LEFT BACK (LB) FIXTURE REV | M20: 14 | N20: Y110D | O20: SPARE | AA20: SW ON↑ | AB20: 1, 3, 5
D21: 15 | E21: X100E | F21: LEFT FRONT (LF) FIXTURE FWD | M21: 15 | N21: Y110E | O21: SPARE | S21: STATION No. | T21: Part No. | U21: 번호 | V21: I/O | W21: Description | AA21: RS-232 COMM.
D22: 16 | E22: X100F | F22: LEFT FRONT (LF) FIXTURE REV | M22: 16 | N22: Y110F | O22: SPARE | S22: Profile I/O Pannel | AA22: STATION No. | AB22: Part No. | AC22: 번호 | AF22: Description
D23: 17 | E23: X1010 | F23: LIFT PIN GLASS CHECK 01 | M23: 17 | N23: Y1110 | O23: FIXTURE UP | S23: 26 | T23: AJ65VBTCU-68ADVN | U23: 1 | V23: CH1 | W23: PROBE MODULE_1 | Y23: ISE20B
D24: 18 | E24: X1011 | F24: SAMPLE PLATE GLASS CHECK 01 | M24: 18 | N24: Y1111 | O24: SPARE | U24: 2 | V24: CH2 | W24: PROBE MODULE_2 | Y24: ISE20B
D25: 19 | E25: X1012 | F25: LIFT PIN DOWN | M25: 19 | N25: Y1112 | O25: SIGNAL TOWER RED | U25: 3 | V25: CH3 | W25: PROBE MODULE_3 | Y25: ISE20B
D26: 20 | E26: X1013 | F26: LIFT PIN UP | M26: 20 | N26: Y1113 | O26: SIGNAL TOWER YELLOW | U26: 4 | V26: CH4 | W26: PROBE MODULE_4 | Y26: ISE20B | AA26: B RATE | AB26: 4
D27: 21 | E27: X1014 | F27: X0-UNLOADING POSITION (HEAD GANTRY 1) | M27: 21 | N27: Y1114 | O27: SIGNAL TOWER GREEN | U27: 5 | V27: CH5 | W27: PROBE MODULE_5 | Y27: ISE20B | AA27: MODE | AB27: 1
D28: 22 | E28: X1015 | F28: X2-UNLOADING POSITION (HEAD GANTRY 2) | M28: 22 | N28: Y1115 | O28: SPARE | U28: 6 | V28: CH6 | W28: ZERO POSITION_1 | Y28: ISE20B | AA28: SW ON↑ | AB28: 1, 3, 5
D29: 23 | E29: X1016 | F29: SP_X-UNLOADING POSITION (SAMPLE PLATE) | M29: 23 | N29: Y1116 | O29: SIGNAL TOWER BUZZER 01 | U29: 7 | V29: CH7 | W29: ZERO POSITION_2 | Y29: ISE20B | AA29: RS-232 COMM.
D30: 24 | E30: X1017 | F30: Y0-UNLOADING POSITION (HEAD1) | M30: 24 | N30: Y1117 | O30: SPARE | U30: 8 | V30: CH8 | W30: ZERO POSITION_3 | Y30: ISE20B | AA30: STATION No. | AB30: Part No. | AC30: 번호 | AF30: Description
D31: 25 | E31: X1018 | F31: Y1-UNLOADING POSITION (HEAD2) | M31: 25 | N31: Y1118 | O31: VOICE BUZZER CH1 ON
D32: 26 | E32: X1019 | F32: Y2-UNLOADING POSITION (HEAD3) | M32: 26 | N32: Y1119 | O32: VOICE BUZZER CH2 ON | S32: B RATE | T32: 4
D33: 27 | E33: X101A | F33: Y3-UNLOADING POSITION (HEAD4) | M33: 27 | N33: Y111A | O33: VOICE BUZZER CH3 ON | S33: MODE | T33: 3
D34: 28 | E34: X101B | F34: X4-UNLOADING POSITION (PROBE GANTRY 1) | M34: 28 | N34: Y111B | O34: VOICE BUZZER CH4 ON | S34: ANALOG INPUT | AA34: B RATE | AB34: 4
D35: 29 | E35: X101C | F35: X6-UNLOADING POSITION (PROBE GANTRY 2) | M35: 29 | N35: Y111C | O35: VOICE BUZZER CH5 ON (RESERVED) | AA35: MODE | AB35: 1
D36: 30 | E36: X101D | F36: X8-UNLOADING POSITION (PROBE GANTRY 3) | M36: 30 | N36: Y111D | O36: VOICE BUZZER CH6 ON (RESERVED) | S36: STATION No. | T36: Part No. | U36: 번호 | V36: I/O | W36: Description | AA36: SW ON↑ | AB36: 1, 3, 5
D37: 31 | E37: X101E | F37: X10-UNLOADING POSITION (PROBE GANTRY 4) | M37: 31 | N37: Y111E | O37: VOICE BUZZER CH7 ON (RESERVED) | S37: HI-BOX | AA37: RS-232 COMM.
D38: 32 | E38: X101F | F38: X12-UNLOADING POSITION (PROBE GANTRY 5) | M38: 32 | N38: Y111F | O38: VOICE BUZZER CH8 ON (RESERVED) | S38: 27 | T38: AJ65VBTCU-68ADVN | U38: 1 | V38: CH1 | W38: ZERO POSITION_4 | Y38: ISE20B | AA38: STATION No. | AB38: Part No. | AC38: 번호 | AF38: Description
B39: EQ | K39: PROFILE | U39: 2 | V39: CH2 | W39: ZERO POSITION_5 | Y39: ISE20B
B40: 2 | C40: AJ65SBTB1-32D1 | D40: 33 | E40: X1020 | F40: FRONT LEFT (UFL) FIXTURE UP | K40: 10 | L40: AJ65SBTB1-32T1 | M40: 33 | N40: Y1120 | O40: PROBE CARD ZERO POSITION 01 UNLOCK | U40: 3 | V40: CH3 | W40: PLATE BLOW_VACUUM 01 | Y40: ZSE20BF
...

Sheet 2. T-Memory Map
B2: T4000번지 Memory Map | I2: Option
I3: PACC
B4: No | D4: X Memory | E4: Address | F4: Comment
B5: 1 | C5: FIXTURE | D5: X1000 | E5: T4000 | F5: Front Fixture FWD 01 | H5: EQ, Chamber | I5: T4000 ~ T4699
B6: 2 | D6: X1001 | E6: T4001 | F6: Front Fixture REV 01 | H6: PACC | I6: T4700 ~ T4999
B7: 3 | D7: X1002 | E7: T4002 | F7: Front Fixture FWD 02
B8: 4 | D8: X1003 | E8: T4003 | F8: Front Fixture REV 02
B9: 5 | D9: X1004 | E9: T4004 | F9: Right Fixture FWD 01
B10: 6 | D10: X1005 | E10: T4005 | F10: Right Fixture REV 01
B11: 7 | D11: X1006 | E11: T4006 | F11: Right Fixture FWD 02
B12: 8 | D12: X1007 | E12: T4007 | F12: Right Fixture REV 02
B13: 9 | D13: X1008 | E13: T4008 | F13: Back Fixture FWD 01
B14: 10 | D14: X1009 | E14: T4009 | F14: Back Fixture REV 01
B15: 11 | D15: X100A | E15: T4010 | F15: Back Fixture FWD 02
B16: 12 | D16: X100B | E16: T4011 | F16: Back Fixture REV 02
B17: 13 | D17: X100C | E17: T4012 | F17: Left Fixture FWD 01
B18: 14 | D18: X100D | E18: T4013 | F18: Left Fixture REV 01
... B20: 16 | D20: X100F | E20: T4015 | F20: Left Fixture REV 02
B21: 17 | E21: T4016
B22: 18 | E22: T4017
B23: 19 | E23: T4018
B24: 20 | E24: T4019
B25: 21 | C25: FIXTURE UP / DOWN | D25: X1020 | E25: T4020 | F25: Front Fixture Up 01
B26: 22 | D26: X1021 | E26: T4021 | F26: Front Fixture Down 01
B27: 23 | D27: X1022 | E27: T4022 | F27: Front Fixture Up 02
B28: 24 | D28: X1023 | E28: T4023 | F28: Front Fixture Down 02
B29: 25 | D29: X1024 | E29: T4024 | F29: Right Fixture Up 01
B30: 26 | D30: X1025 | E30: T4025 | F30: Right Fixture Down 01
B31: 27 | D31: X1026 | E31: T4026 | F31: Right Fixture Up 02
B32: 28 | D32: X1027 | E32: T4027 | F32: Right Fixture Down 02
B33: 29 | D33: X1028 | E33: T4028 | F33: Back Fixture Up 01
B34: 30 | D34: X1029 | E34: T4029 | F34: Back Fixture Down 01
B35: 31 | D35: X102A | E35: T4030 | F35: Back Fixture Up 02
B36: 32 | D36: X102B | E36: T4031 | F36: Back Fixture Down 02
B37: 33 | D37: X102C | E37: T4032 | F37: Left Fixture Up 01
... B40: 36 | D40: X102F | E40: T4035 | F40: Left Fixture Down 02
B41: 37 | E41: T4036
B42: 38 | E42: T4037
B43: 39 | E43: T4038
B44: 40 | E44: T4039
...

Sheet 3. M-Memory Map
B2: M4000번지 Memory Map
B3: No | C3: T Matching | D3: Address | E3: T Memory | G3: 6K / 8K / SE / STCM | H3: T Memory | J3: SE / OM (Chamber) | K3: T Memory | M3: LO (PACC)
B4: 1 | D4: M4000 | F4: PLC STATE | G4: EQ Ready State To EQ | I4: PLC STATE | J4: EQ Ready State To EQ | L4: PLC STATE | M4: EQ Ready State To EQ
B5: 2 | D5: M4001 | G5: EQ Load State To EQ | J5: EQ Load State To EQ | M5: EQ Load State To EQ
B6: 3 | D6: M4002 | G6: EQ Measure State To EQ | J6: EQ Measure State To EQ | M6: EQ Measure State To EQ
B7: 4 | D7: M4003
B8: 5 | D8: M4004
B9: 6 | D9: M4005 | G9: Initial Complete | J9: Initial Complete | M9: Initial Complete
B10: 7 | D10: M4006
B11: 8 | D11: M4007
B12: 9 | D12: M4008 | G12: PLC Alarm | J12: PLC Alarm | M12: PLC Alarm
B13: 10 | D13: M4009 | G13: PLC Warning | J13: PLC Warning | M13: PLC Warning
B14: 11 | C14: T4080 | D14: M4010 | E14: T4080 | F14: EMO | G14: EMO Push 01 | H14: T4080 | I14: EMO | J14: EMO Push 01 | K14: T4080 | L14: EMO | M14: EMO Push 01
B15: 12 | C15: T4081 | D15: M4011 | E15: T4081 | G15: EMO Push 02 | H15: T4081 | J15: EMO Push 02 | K15: T4081 | M15: EMO Push 02
B16: 13 | C16: T4082 | D16: M4012 | E16: T4082 | G16: EMO Push 03 | H16: T4082 | J16: EMO Push 03 | K16: T4082 | M16: EMO Push 03
B17: 14 | C17: T4083 | D17: M4013 | E17: T4083 | G17: EMO Push 04 | H17: T4083 | J17: EMO Push 04 | K17: T4083 | M17: EMO Push 04
B18: 15 | C18: T4084 | D18: M4014 | E18: T4084 | G18: EMO Push 05 | H18: T4084 | J18: EMO Push 05 | K18: T4084 | M18: EMO Push 05
B19: 16 | C19: T4085 | D19: M4015 | E19: T4085 | G19: EMO Push 06 | H19: T4085 | J19: EMO Push 06 | K19: T4085 | M19: EMO Push 06
B20: 17 | C20: T4086 | D20: M4016 | E20: T4086 | G20: EMO Push 07 | H20: T4086 | J20: EMO Push 07 | K20: T4086 | M20: EMO Push 07
B21: 18 | C21: T4087 | D21: M4017 | E21: T4087 | G21: EMO Push 08 | H21: T4087 | J21: EMO Push 08 | K21: T4087 | M21: EMO Push 08
B22: 19 | C22: T4088 | D22: M4018 | E22: T4088 | G22: EMO Push 09 | H22: T4088 | J22: EMO Push 09 | K22: T4088 | M22: EMO Push 09
B23: 20 | C23: T4089 | D23: M4019 | E23: T4089 | G23: EMO Push 10 | H23: T4089 | J23: EMO Push 10 | K23: T4089 | M23: EMO Push 10
B24: 21 | C24: T4090 | D24: M4020 | E24: T4090 | F24: DOOR | G24: Door Open 01 | H24: T4090 | I24: DOOR | J24: Door Open 01 | K24: T4090 | L24: DOOR | M24: Door Open 01
B25: 22 | C25: T4091 | D25: M4021 | E25: T4091 | G25: Door Open 02 | H25: T4091 | J25: Door Open 02 | K25: T4091 | M25: Door Open 02
B26: 23 | C26: T4092 | D26: M4022 | E26: T4092 | G26: Door Open 03 | H26: T4092 | J26: Door Open 03 | K26: T4092 | M26: Door Open 03
B27: 24 | C27: T4093 | D27: M4023 | E27: T4093 | G27: Door Open 04 | H27: T4093 | J27: Door Open 04 | K27: T4093 | M27: Door Open 04
B28: 25 | C28: T4094 | D28: M4024 | E28: T4094 | G28: Door Open 05 | H28: T4094 | J28: Door Open 05 | K28: T4094 | M28: Door Open 05
B29: 26 | C29: T4095 | D29: M4025 | E29: T4095 | G29: Door Open 06 | H29: T4095 | J29: Door Open 06 | K29: T4095 | M29: Door Open 06
B30: 27 | D30: M4026 | E30: T4096 | G30: Door Open 07 | H30: T4096 | J30: Door Open 07 | K30: T4096 | M30: Door Open 07
B31: 28 | D31: M4027 | E31: T4097 | G31: Door Open 08 | H31: T4097 | J31: Door Open 08 | K31: T4097 | M31: Door Open 08
B32: 29 | D32: M4028 | E32: T4098 | G32: Door Open 09 | H32: T4098 | J32: Door Open 09 | K32: T4098 | M32: Door Open 09
B33: 30 | D33: M4029 | E33: T4099 | G33: Door Open 10 | H33: T4099 | J33: Door Open 10 | K33: T4099 | M33: Door Open 10
B34: 31 | C34: T4100 | D34: M4030 | E34: T4100 | F34: DOOR UNLOCK | G34: Door Unlock 01 | H34: T4100 | I34: DOOR UNLOCK | J34: Door Unlock 01 | K34: T4100 | L34: DOOR UNLOCK | M34: Door Unlock 01
B35: 32 | C35: T4101 | D35: M4031 | E35: T4101 | G35: Door Unlock 02 | H35: T4101 | J35: Door Unlock 02 | K35: T4101 | M35: Door Unlock 02
B36: 33 | C36: T4102 | D36: M4032 | E36: T4102 | G36: Door Unlock 03 | H36: T4102 | J36: Door Unlock 03 | K36: T4102 | M36: Door Unlock 03
B37: 34 | C37: T4103 | D37: M4033 | E37: T4103 | G37: Door Unlock 04 | H37: T4103 | J37: Door Unlock 04 | K37: T4103 | M37: Door Unlock 04
B38: 35 | C38: T4104 | D38: M4034 | E38: T4104 | G38: Door Unlock 05 | H38: T4104 | J38: Door Unlock 05 | K38: T4104 | M38: Door Unlock 05
B39: 36 | C39: T4105 | D39: M4035 | E39: T4105 | G39: Door Unlock 06 | H39: T4105 | J39: Door Unlock 06 | K39: T4105 | M39: Door Unlock 06
B40: 37 | D40: M4036 | E40: T4106 | G40: Door Unlock 07 | H40: T4106 | J40: Door Unlock 07 | K40: T4106 | M40: Door Unlock 07
B41: 38 | D41: M4037 | E41: T4107 | G41: Door Unlock 08 | H41: T4107 | J41: Door Unlock 08 | K41: T4107 | M41: Door Unlock 08
...

Sheet IO List Map
B1: 2022.01.10
E2: A접 센서 | F2: 검정
B3: B RATE | C3: 4 | E3: B접 센서 | F3: 빨강 | K3: B RATE | L3: 4 | S3: B RATE | T3: ='1. IO 작성 Map'!T2 -> 4 | AA3: B RATE | AB3: 4
B4: INPUT | K4: OUTPUT | S4: MODE | T4: ='1. IO 작성 Map'!T3 -> 3 | AA4: MODE | AB4: 1
S5: ANALOG INPUT | AA5: SW ON↑ | AB5: 1, 3, 5
B6: STATION No. | C6: Part No. | D6: 번호 | E6: I/O | F6: Description | G6: T4000 | H6: M4000 | K6: STATION No. | L6: Part No. | M6: 번호 | N6: I/O | O6: Description | P6: M4500 | AA6: RS-232 COMM.
B7: ='1. IO 작성 Map'!B6:F6 -> EQ | K7: ='1. IO 작성 Map'!K6:Q6 -> PROFILE | S7: STATION No. | T7: Part No. | U7: 번호 | V7: I/O | W7: Description | AA7: STATION No. | AB7: Part No. | AC7: 번호 | AF7: Description
B8: ='1. IO 작성 Map'!B7:B38 -> 0 | C8: ='1. IO 작성 Map'!C7:C38 -> 0 | D8: ='1. IO 작성 Map'!D7 -> 1 | E8: ='1. IO 작성 Map'!E7 -> X1000 | F8: ='1. IO 작성 Map'!F7 -> FRONT LEFT (FL) FIXTURE FWD | G8: =VLOOKUP(E8,'2. T-Memory Map'!$D$5:$E$1004,2,FALSE) -> T4000 | H8: =VLOOKUP(G8,'3. M-Memory Map'!$C$4:$D$503,2,FALSE) -> M4430 | K8: ='1. IO 작성 Map'!K7:K38 -> 0 | L8: ='1. IO 작성 Map'!L7:L38 -> 0 | M8: ='1. IO 작성 Map'!M7 -> 1 | N8: ='1. IO 작성 Map'!N7 -> Y1100 | O8: ='1. IO 작성 Map'!O7 -> FRONT FIXTURE FWD | P8: =VLOOKUP(N8,'3. M-Memory Map'!$C$508:$D$1007,2,FALSE) -> M4791 | S8: ='1. IO 작성 Map'!S7:X7 -> Profile I/O Pannel
D9: ='1. IO 작성 Map'!D8 -> 2 | E9: ='1. IO 작성 Map'!E8 -> X1001 | F9: ='1. IO 작성 Map'!F8 -> FRONT LEFT (FL) FIXTURE REV | G9: =VLOOKUP(E9,'2. T-Memory Map'!$D$5:$E$1004,2,FALSE) -> T4001 | H9: =VLOOKUP(G9,'3. M-Memory Map'!$C$4:$D$503,2,FALSE) -> M4431 | M9: ='1. IO 작성 Map'!M8 -> 2 | N9: ='1. IO 작성 Map'!N8 -> Y1101 | O9: ='1. IO 작성 Map'!O8 -> RIGHT FIXTURE FWD | P9: =VLOOKUP(N9,'3. M-Memory Map'!$C$508:$D$1007,2,FALSE) -> M4792 | S9: ='1. IO 작성 Map'!S8:S15 -> 0 | T9: ='1. IO 작성 Map'!T8:T15 -> 0 | U9: ='1. IO 작성 Map'!U8 -> 1 | V9: ='1. IO 작성 Map'!V8 -> CH1 | W9: ='1. IO 작성 Map'!W8 -> CDA 01 | X9: ='1. IO 작성 Map'!X8 -> 0 | Y9: ='1. IO 작성 Map'!Y8 -> ISE20B | AA9: ='1. IO 작성 Map'!AA8 -> 0 | AB9: ='1. IO 작성 Map'!AB8 -> 0 | AC9: ='1. IO 작성 Map'!AC8 -> 0 | AD9: ='1. IO 작성 Map'!AD8:AE8 -> 0 | AF9: ='1. IO 작성 Map'!AF8 -> 0 | AG9: ='1. IO 작성 Map'!AG8 -> 0 | AH9: ='1. IO 작성 Map'!AH8 -> 0
D10: ='1. IO 작성 Map'!D9 -> 3 | E10: ='1. IO 작성 Map'!E9 -> X1002 | F10: ='1. IO 작성 Map'!F9 -> FRONT RIGHT (FR) FIXTURE FWD | G10: =VLOOKUP(E10,'2. T-Memory Map'!$D$5:$E$1004,2,FALSE) -> T4002 | H10: =VLOOKUP(G10,'3. M-Memory Map'!$C$4:$D$503,2,FALSE) -> M4432 | M10: ='1. IO 작성 Map'!M9 -> 3 | N10: ='1. IO 작성 Map'!N9 -> Y1102 | O10: ='1. IO 작성 Map'!O9 -> BACK FIXTURE FWD | P10: =VLOOKUP(N10,'3. M-Memory Map'!$C$508:$D$1007,2,FALSE) -> M4793 | U10: ='1. IO 작성 Map'!U9 -> 2 | V10: ='1. IO 작성 Map'!V9 -> CH2 | W10: ='1. IO 작성 Map'!W9 -> CDA 02 | X10: ='1. IO 작성 Map'!X9 -> 0 | Y10: ='1. IO 작성 Map'!Y9 -> ISE20B
D11: ='1. IO 작성 Map'!D10 -> 4 | E11: ='1. IO 작성 Map'!E10 -> X1003 | F11: ='1. IO 작성 Map'!F10 -> FRONT RIGHT (FR) FIXTURE REV | G11: =VLOOKUP(E11,'2. T-Memory Map'!$D$5:$E$1004,2,FALSE) -> T4003 | H11: =VLOOKUP(G11,'3. M-Memory Map'!$C$4:$D$503,2,FALSE) -> M4433 | M11: ='1. IO 작성 Map'!M10 -> 4 | N11: ='1. IO 작성 Map'!N10 -> Y1103 | O11: ='1. IO 작성 Map'!O10 -> LEFT FIXTURE FWD | P11: =VLOOKUP(N11,'3. M-Memory Map'!$C$508:$D$1007,2,FALSE) -> M4794 | U11: ='1. IO 작성 Map'!U10 -> 3 | V11: ='1. IO 작성 Map'!V10 -> CH3 | W11: ='1. IO 작성 Map'!W10 -> CDA 03 | X11: ='1. IO 작성 Map'!X10 -> 0 | Y11: ='1. IO 작성 Map'!Y10 -> ISE20B | AA11: B RATE | AB11: 4
D12: ='1. IO 작성 Map'!D11 -> 5 | E12: ='1. IO 작성 Map'!E11 -> X1004 | F12: ='1. IO 작성 Map'!F11 -> RIGHT FRONT (RF) FIXTURE FWD | G12: =VLOOKUP(E12,'2. T-Memory Map'!$D$5:$E$1004,2,FALSE) -> T4004 | H12: =VLOOKUP(G12,'3. M-Memory Map'!$C$4:$D$503,2,FALSE) -> M4434 | M12: ='1. IO 작성 Map'!M11 -> 5 | N12: ='1. IO 작성 Map'!N11 -> Y1104 | O12: ='1. IO 작성 Map'!O11 -> SPARE | P12: =VLOOKUP(N12,'3. M-Memory Map'!$C$508:$D$1007,2,FALSE) -> #N/A | U12: ='1. IO 작성 Map'!U11 -> 4 | V12: ='1. IO 작성 Map'!V11 -> CH4 | W12: ='1. IO 작성 Map'!W11 -> FIXTURE 01 | X12: ='1. IO 작성 Map'!X11 -> 0 | Y12: ='1. IO 작성 Map'!Y11 -> ISE20B | AA12: MODE | AB12: 1
D13: ='1. IO 작성 Map'!D12 -> 6 | E13: ='1. IO 작성 Map'!E12 -> X1005 | F13: ='1. IO 작성 Map'!F12 -> RIGHT FRONT (RF) FIXTURE REV | G13: =VLOOKUP(E13,'2. T-Memory Map'!$D$5:$E$1004,2,FALSE) -> T4005 | H13: =VLOOKUP(G13,'3. M-Memory Map'!$C$4:$D$503,2,FALSE) -> M4435 | M13: ='1. IO 작성 Map'!M12 -> 6 | N13: ='1. IO 작성 Map'!N12 -> Y1105 | O13: ='1. IO 작성 Map'!O12 -> SPARE | P13: =VLOOKUP(N13,'3. M-Memory Map'!$C$508:$D$1007,2,FALSE) -> #N/A | U13: ='1. IO 작성 Map'!U12 -> 5 | V13: ='1. IO 작성 Map'!V12 -> CH5 | W13: ='1. IO 작성 Map'!W12 -> FIXTURE 02 | X13: ='1. IO 작성 Map'!X12 -> 0 | Y13: ='1. IO 작성 Map'!Y12 -> ISE20B | AA13: SW ON↑ | AB13: 1, 3, 5
D14: ='1. IO 작성 Map'!D13 -> 7 | E14: ='1. IO 작성 Map'!E13 -> X1006 | F14: ='1. IO 작성 Map'!F13 -> RIGHT BACK (RB) FIXTURE FWD | G14: =VLOOKUP(E14,'2. T-Memory Map'!$D$5:$E$1004,2,FALSE) -> T4006 | H14: =VLOOKUP(G14,'3. M-Memory Map'!$C$4:$D$503,2,FALSE) -> M4436 | M14: ='1. IO 작성 Map'!M13 -> 7 | N14: ='1. IO 작성 Map'!N13 -> Y1106 | O14: ='1. IO 작성 Map'!O13 -> SAMPLE PLATE BLOWING | P14: =VLOOKUP(N14,'3. M-Memory Map'!$C$508:$D$1007,2,FALSE) -> M4810 | U14: ='1. IO 작성 Map'!U13 -> 6 | V14: ='1. IO 작성 Map'!V13 -> CH6 | W14: ='1. IO 작성 Map'!W13 -> ISOLATOR 01 | X14: ='1. IO 작성 Map'!X13 -> 0 | Y14: ='1. IO 작성 Map'!Y13 -> ISE20B | AA14: RS-232 COMM.
D15: ='1. IO 작성 Map'!D14 -> 8 | E15: ='1. IO 작성 Map'!E14 -> X1007 | F15: ='1. IO 작성 Map'!F14 -> RIGHT BACK (RB) FIXTURE REV | G15: =VLOOKUP(E15,'2. T-Memory Map'!$D$5:$E$1004,2,FALSE) -> T4007 | H15: =VLOOKUP(G15,'3. M-Memory Map'!$C$4:$D$503,2,FALSE) -> M4437 | M15: ='1. IO 작성 Map'!M14 -> 8 | N15: ='1. IO 작성 Map'!N14 -> Y1107 | O15: ='1. IO 작성 Map'!O14 -> SPARE | P15: =VLOOKUP(N15,'3. M-Memory Map'!$C$508:$D$1007,2,FALSE) -> #N/A | U15: ='1. IO 작성 Map'!U14 -> 7 | V15: ='1. IO 작성 Map'!V14 -> CH7 | W15: ='1. IO 작성 Map'!W14 -> ISOLATOR 02 | X15: ='1. IO 작성 Map'!X14 -> 0 | Y15: ='1. IO 작성 Map'!Y14 -> ISE20B | AA15: STATION No. | AB15: Part No. | AC15: 번호 | AF15: Description
D16: ='1. IO 작성 Map'!D15 -> 9 | E16: ='1. IO 작성 Map'!E15 -> X1008 | F16: ='1. IO 작성 Map'!F15 -> BACK RIGHT (BR) FIXTURE FWD | G16: =VLOOKUP(E16,'2. T-Memory Map'!$D$5:$E$1004,2,FALSE) -> T4008 | H16: =VLOOKUP(G16,'3. M-Memory Map'!$C$4:$D$503,2,FALSE) -> M4438 | M16: ='1. IO 작성 Map'!M15 -> 9 | N16: ='1. IO 작성 Map'!N15 -> Y1108 | O16: ='1. IO 작성 Map'!O15 -> SAMPLE PLATE VACUUM | P16: =VLOOKUP(N16,'3. M-Memory Map'!$C$508:$D$1007,2,FALSE) -> M4830 | U16: ='1. IO 작성 Map'!U15 -> 8 | V16: ='1. IO 작성 Map'!V15 -> CH8 | W16: ='1. IO 작성 Map'!W15 -> SHUTTER | X16: ='1. IO 작성 Map'!X15 -> 0 | Y16: ='1. IO 작성 Map'!Y15 -> ISE20B
D17: ='1. IO 작성 Map'!D16 -> 10 | E17: ='1. IO 작성 Map'!E16 -> X1009 | F17: ='1. IO 작성 Map'!F16 -> BACK RIGHT (BR) FIXTURE REV | G17: =VLOOKUP(E17,'2. T-Memory Map'!$D$5:$E$1004,2,FALSE) -> T4009 | H17: =VLOOKUP(G17,'3. M-Memory Map'!$C$4:$D$503,2,FALSE) -> M4439 | M17: ='1. IO 작성 Map'!M16 -> 10 | N17: ='1. IO 작성 Map'!N16 -> Y1109 | O17: ='1. IO 작성 Map'!O16 -> SPARE | P17: =VLOOKUP(N17,'3. M-Memory Map'!$C$508:$D$1007,2,FALSE) -> #N/A | AA17: ='1. IO 작성 Map'!AA16 -> 0 | AB17: ='1. IO 작성 Map'!AB16 -> 0 | AC17: ='1. IO 작성 Map'!AC16 -> 0 | AD17: ='1. IO 작성 Map'!AD16:AE16 -> 0 | AF17: ='1. IO 작성 Map'!AF16 -> 0 | AG17: ='1. IO 작성 Map'!AG16 -> 0 | AH17: ='1. IO 작성 Map'!AH16 -> 0
D18: ='1. IO 작성 Map'!D17 -> 11 | E18: ='1. IO 작성 Map'!E17 -> X100A | F18: ='1. IO 작성 Map'!F17 -> BACK LEFT (BL) FIXTURE FWD | G18: =VLOOKUP(E18,'2. T-Memory Map'!$D$5:$E$1004,2,FALSE) -> T4010 | H18: =VLOOKUP(G18,'3. M-Memory Map'!$C$4:$D$503,2,FALSE) -> M4440 | M18: ='1. IO 작성 Map'!M17 -> 11 | N18: ='1. IO 작성 Map'!N17 -> Y110A | O18: ='1. IO 작성 Map'!O17 -> SHUTTER OPEN | P18: =VLOOKUP(N18,'3. M-Memory Map'!$C$508:$D$1007,2,FALSE) -> M4541 | S18: B RATE | T18: ='1. IO 작성 Map'!T17 -> 4
D19: ='1. IO 작성 Map'!D18 -> 12 | E19: ='1. IO 작성 Map'!E18 -> X100B | F19: ='1. IO 작성 Map'!F18 -> BACK LEFT (BL) FIXTURE REV | G19: =VLOOKUP(E19,'2. T-Memory Map'!$D$5:$E$1004,2,FALSE) -> T4011 | H19: =VLOOKUP(G19,'3. M-Memory Map'!$C$4:$D$503,2,FALSE) -> M4441 | M19: ='1. IO 작성 Map'!M18 -> 12 | N19: ='1. IO 작성 Map'!N18 -> Y110B | O19: ='1. IO 작성 Map'!O18 -> SHUTTER CLOSE | P19: =VLOOKUP(N19,'3. M-Memory Map'!$C$508:$D$1007,2,FALSE) -> M4540 | S19: MODE | T19: ='1. IO 작성 Map'!T18 -> 3 | AA19: B RATE | AB19: 4
D20: ='1. IO 작성 Map'!D19 -> 13 | E20: ='1. IO 작성 Map'!E19 -> X100C | F20: ='1. IO 작성 Map'!F19 -> LEFT BACK (LB) FIXTURE FWD | G20: =VLOOKUP(E20,'2. T-Memory Map'!$D$5:$E$1004,2,FALSE) -> T4012 | H20: =VLOOKUP(G20,'3. M-Memory Map'!$C$4:$D$503,2,FALSE) -> M4442 | M20: ='1. IO 작성 Map'!M19 -> 13 | N20: ='1. IO 작성 Map'!N19 -> Y110C | O20: ='1. IO 작성 Map'!O19 -> SPARE | P20: =VLOOKUP(N20,'3. M-Memory Map'!$C$508:$D$1007,2,FALSE) -> #N/A | S20: ANALOG INPUT | AA20: MODE | AB20: 1
D21: ='1. IO 작성 Map'!D20 -> 14 | E21: ='1. IO 작성 Map'!E20 -> X100D | F21: ='1. IO 작성 Map'!F20 -> LEFT BACK (LB) FIXTURE REV | G21: =VLOOKUP(E21,'2. T-Memory Map'!$D$5:$E$1004,2,FALSE) -> T4013 | H21: =VLOOKUP(G21,'3. M-Memory Map'!$C$4:$D$503,2,FALSE) -> M4443 | M21: ='1. IO 작성 Map'!M20 -> 14 | N21: ='1. IO 작성 Map'!N20 -> Y110D | O21: ='1. IO 작성 Map'!O20 -> SPARE | P21: =VLOOKUP(N21,'3. M-Memory Map'!$C$508:$D$1007,2,FALSE) -> #N/A | AA21: SW ON↑ | AB21: 1, 3, 5
D22: ='1. IO 작성 Map'!D21 -> 15 | E22: ='1. IO 작성 Map'!E21 -> X100E | F22: ='1. IO 작성 Map'!F21 -> LEFT FRONT (LF) FIXTURE FWD | G22: =VLOOKUP(E22,'2. T-Memory Map'!$D$5:$E$1004,2,FALSE) -> T4014 | H22: =VLOOKUP(G22,'3. M-Memory Map'!$C$4:$D$503,2,FALSE) -> M4444 | M22: ='1. IO 작성 Map'!M21 -> 15 | N22: ='1. IO 작성 Map'!N21 -> Y110E | O22: ='1. IO 작성 Map'!O21 -> SPARE | P22: =VLOOKUP(N22,'3. M-Memory Map'!$C$508:$D$1007,2,FALSE) -> #N/A | S22: STATION No. | T22: Part No. | U22: 번호 | V22: I/O | W22: Description | AA22: RS-232 COMM.
D23: ='1. IO 작성 Map'!D22 -> 16 | E23: ='1. IO 작성 Map'!E22 -> X100F | F23: ='1. IO 작성 Map'!F22 -> LEFT FRONT (LF) FIXTURE REV | G23: =VLOOKUP(E23,'2. T-Memory Map'!$D$5:$E$1004,2,FALSE) -> T4015 | H23: =VLOOKUP(G23,'3. M-Memory Map'!$C$4:$D$503,2,FALSE) -> M4445 | M23: ='1. IO 작성 Map'!M22 -> 16 | N23: ='1. IO 작성 Map'!N22 -> Y110F | O23: ='1. IO 작성 Map'!O22 -> SPARE | P23: =VLOOKUP(N23,'3. M-Memory Map'!$C$508:$D$1007,2,FALSE) -> #N/A | S23: ='1. IO 작성 Map'!S22:X22 -> Profile I/O Pannel | AA23: STATION No. | AB23: Part No. | AC23: 번호 | AF23: Description
D24: ='1. IO 작성 Map'!D23 -> 17 | E24: ='1. IO 작성 Map'!E23 -> X1010 | F24: ='1. IO 작성 Map'!F23 -> LIFT PIN GLASS CHECK 01 | G24: =VLOOKUP(E24,'2. T-Memory Map'!$D$5:$E$1004,2,FALSE) -> T4160 | H24: =VLOOKUP(G24,'3. M-Memory Map'!$C$4:$D$503,2,FALSE) -> M4090 | M24: ='1. IO 작성 Map'!M23 -> 17 | N24: ='1. IO 작성 Map'!N23 -> Y1110 | O24: ='1. IO 작성 Map'!O23 -> FIXTURE UP | P24: =VLOOKUP(N24,'3. M-Memory Map'!$C$508:$D$1007,2,FALSE) -> M4795 | S24: ='1. IO 작성 Map'!S23:S30 -> 0 | T24: ='1. IO 작성 Map'!T23:T30 -> 0 | U24: ='1. IO 작성 Map'!U23 -> 1 | V24: ='1. IO 작성 Map'!V23 -> CH1 | W24: ='1. IO 작성 Map'!W23 -> PROBE MODULE_1 | X24: ='1. IO 작성 Map'!X23 -> 0 | Y24: ='1. IO 작성 Map'!Y23 -> ISE20B
D25: ='1. IO 작성 Map'!D24 -> 18 | E25: ='1. IO 작성 Map'!E24 -> X1011 | F25: ='1. IO 작성 Map'!F24 -> SAMPLE PLATE GLASS CHECK 01 | G25: =VLOOKUP(E25,'2. T-Memory Map'!$D$5:$E$1004,2,FALSE) -> T4165 | H25: =VLOOKUP(G25,'3. M-Memory Map'!$C$4:$D$503,2,FALSE) -> M4095 | M25: ='1. IO 작성 Map'!M24 -> 18 | N25: ='1. IO 작성 Map'!N24 -> Y1111 | O25: ='1. IO 작성 Map'!O24 -> SPARE | P25: =VLOOKUP(N25,'3. M-Memory Map'!$C$508:$D$1007,2,FALSE) -> #N/A | U25: ='1. IO 작성 Map'!U24 -> 2 | V25: ='1. IO 작성 Map'!V24 -> CH2 | W25: ='1. IO 작성 Map'!W24 -> PROBE MODULE_2 | X25: ='1. IO 작성 Map'!X24 -> 0 | Y25: ='1. IO 작성 Map'!Y24 -> ISE20B | AA25: ='1. IO 작성 Map'!AA24 -> 0 | AB25: ='1. IO 작성 Map'!AB24 -> 0 | AC25: ='1. IO 작성 Map'!AC24 -> 0 | AD25: ='1. IO 작성 Map'!AD24:AE24 -> 0 | AF25: ='1. IO 작성 Map'!AF24 -> 0 | AG25: ='1. IO 작성 Map'!AG24 -> 0 | AH25: ='1. IO 작성 Map'!AH24 -> 0
D26: ='1. IO 작성 Map'!D25 -> 19 | E26: ='1. IO 작성 Map'!E25 -> X1012 | F26: ='1. IO 작성 Map'!F25 -> LIFT PIN DOWN | G26: =VLOOKUP(E26,'2. T-Memory Map'!$D$5:$E$1004,2,FALSE) -> T4231 | H26: =VLOOKUP(G26,'3. M-Memory Map'!$C$4:$D$503,2,FALSE) -> M4161 | M26: ='1. IO 작성 Map'!M25 -> 19 | N26: ='1. IO 작성 Map'!N25 -> Y1112 | O26: ='1. IO 작성 Map'!O25 -> SIGNAL TOWER RED | P26: =VLOOKUP(N26,'3. M-Memory Map'!$C$508:$D$1007,2,FALSE) -> M4930 | U26: ='1. IO 작성 Map'!U25 -> 3 | V26: ='1. IO 작성 Map'!V25 -> CH3 | W26: ='1. IO 작성 Map'!W25 -> PROBE MODULE_3 | X26: ='1. IO 작성 Map'!X25 -> 0 | Y26: ='1. IO 작성 Map'!Y25 -> ISE20B
D27: ='1. IO 작성 Map'!D26 -> 20 | E27: ='1. IO 작성 Map'!E26 -> X1013 | F27: ='1. IO 작성 Map'!F26 -> LIFT PIN UP | G27: =VLOOKUP(E27,'2. T-Memory Map'!$D$5:$E$1004,2,FALSE) -> T4230 | H27: =VLOOKUP(G27,'3. M-Memory Map'!$C$4:$D$503,2,FALSE) -> M4160 | M27: ='1. IO 작성 Map'!M26 -> 20 | N27: ='1. IO 작성 Map'!N26 -> Y1113 | O27: ='1. IO 작성 Map'!O26 -> SIGNAL TOWER YELLOW | P27: =VLOOKUP(N27,'3. M-Memory Map'!$C$508:$D$1007,2,FALSE) -> M4931 | U27: ='1. IO 작성 Map'!U26 -> 4 | V27: ='1. IO 작성 Map'!V26 -> CH4 | W27: ='1. IO 작성 Map'!W26 -> PROBE MODULE_4 | X27: ='1. IO 작성 Map'!X26 -> 0 | Y27: ='1. IO 작성 Map'!Y26 -> ISE20B | AA27: B RATE | AB27: 4
D28: ='1. IO 작성 Map'!D27 -> 21 | E28: ='1. IO 작성 Map'!E27 -> X1014 | F28: ='1. IO 작성 Map'!F27 -> X0-UNLOADING POSITION (HEAD GANTRY 1) | G28: =VLOOKUP(E28,'2. T-Memory Map'!$D$5:$E$1004,2,FALSE) -> T4240 | H28: =VLOOKUP(G28,'3. M-Memory Map'!$C$4:$D$503,2,FALSE) -> M4170 | M28: ='1. IO 작성 Map'!M27 -> 21 | N28: ='1. IO 작성 Map'!N27 -> Y1114 | O28: ='1. IO 작성 Map'!O27 -> SIGNAL TOWER GREEN | P28: =VLOOKUP(N28,'3. M-Memory Map'!$C$508:$D$1007,2,FALSE) -> M4932 | U28: ='1. IO 작성 Map'!U27 -> 5 | V28: ='1. IO 작성 Map'!V27 -> CH5 | W28: ='1. IO 작성 Map'!W27 -> PROBE MODULE_5 | X28: ='1. IO 작성 Map'!X27 -> 0 | Y28: ='1. IO 작성 Map'!Y27 -> ISE20B | AA28: MODE | AB28: 1
D29: ='1. IO 작성 Map'!D28 -> 22 | E29: ='1. IO 작성 Map'!E28 -> X1015 | F29: ='1. IO 작성 Map'!F28 -> X2-UNLOADING POSITION (HEAD GANTRY 2) | G29: =VLOOKUP(E29,'2. T-Memory Map'!$D$5:$E$1004,2,FALSE) -> T4241 | H29: =VLOOKUP(G29,'3. M-Memory Map'!$C$4:$D$503,2,FALSE) -> M4171 | M29: ='1. IO 작성 Map'!M28 -> 22 | N29: ='1. IO 작성 Map'!N28 -> Y1115 | O29: ='1. IO 작성 Map'!O28 -> SPARE | P29: =VLOOKUP(N29,'3. M-Memory Map'!$C$508:$D$1007,2,FALSE) -> #N/A | U29: ='1. IO 작성 Map'!U28 -> 6 | V29: ='1. IO 작성 Map'!V28 -> CH6 | W29: ='1. IO 작성 Map'!W28 -> ZERO POSITION_1 | X29: ='1. IO 작성 Map'!X28 -> 0 | Y29: ='1. IO 작성 Map'!Y28 -> ISE20B | AA29: SW ON↑ | AB29: 1, 3, 5
D30: ='1. IO 작성 Map'!D29 -> 23 | E30: ='1. IO 작성 Map'!E29 -> X1016 | F30: ='1. IO 작성 Map'!F29 -> SP_X-UNLOADING POSITION (SAMPLE PLATE) | G30: =VLOOKUP(E30,'2. T-Memory Map'!$D$5:$E$1004,2,FALSE) -> T4242 | H30: =VLOOKUP(G30,'3. M-Memory Map'!$C$4:$D$503,2,FALSE) -> M4172 | M30: ='1. IO 작성 Map'!M29 -> 23 | N30: ='1. IO 작성 Map'!N29 -> Y1116 | O30: ='1. IO 작성 Map'!O29 -> SIGNAL TOWER BUZZER 01 | P30: =VLOOKUP(N30,'3. M-Memory Map'!$C$508:$D$1007,2,FALSE) -> M4925 | U30: ='1. IO 작성 Map'!U29 -> 7 | V30: ='1. IO 작성 Map'!V29 -> CH7 | W30: ='1. IO 작성 Map'!W29 -> ZERO POSITION_2 | X30: ='1. IO 작성 Map'!X29 -> 0 | Y30: ='1. IO 작성 Map'!Y29 -> ISE20B | AA30: RS-232 COMM.
D31: ='1. IO 작성 Map'!D30 -> 24 | E31: ='1. IO 작성 Map'!E30 -> X1017 | F31: ='1. IO 작성 Map'!F30 -> Y0-UNLOADING POSITION (HEAD1) | G31: =VLOOKUP(E31,'2. T-Memory Map'!$D$5:$E$1004,2,FALSE) -> T4243 | H31: =VLOOKUP(G31,'3. M-Memory Map'!$C$4:$D$503,2,FALSE) -> M4173 | M31: ='1. IO 작성 Map'!M30 -> 24 | N31: ='1. IO 작성 Map'!N30 -> Y1117 | O31: ='1. IO 작성 Map'!O30 -> SPARE | P31: =VLOOKUP(N31,'3. M-Memory Map'!$C$508:$D$1007,2,FALSE) -> #N/A | U31: ='1. IO 작성 Map'!U30 -> 8 | V31: ='1. IO 작성 Map'!V30 -> CH8 | W31: ='1. IO 작성 Map'!W30 -> ZERO POSITION_3 | X31: ='1. IO 작성 Map'!X30 -> 0 | Y31: ='1. IO 작성 Map'!Y30 -> ISE20B | AA31: STATION No. | AB31: Part No. | AC31: 번호 | AF31: Description
D32: ='1. IO 작성 Map'!D31 -> 25 | E32: ='1. IO 작성 Map'!E31 -> X1018 | F32: ='1. IO 작성 Map'!F31 -> Y1-UNLOADING POSITION (HEAD2) | G32: =VLOOKUP(E32,'2. T-Memory Map'!$D$5:$E$1004,2,FALSE) -> T4244 | H32: =VLOOKUP(G32,'3. M-Memory Map'!$C$4:$D$503,2,FALSE) -> M4174 | M32: ='1. IO 작성 Map'!M31 -> 25 | N32: ='1. IO 작성 Map'!N31 -> Y1118 | O32: ='1. IO 작성 Map'!O31 -> VOICE BUZZER CH1 ON | P32: =VLOOKUP(N32,'3. M-Memory Map'!$C$508:$D$1007,2,FALSE) -> #N/A
D33: ='1. IO 작성 Map'!D32 -> 26 | E33: ='1. IO 작성 Map'!E32 -> X1019 | F33: ='1. IO 작성 Map'!F32 -> Y2-UNLOADING POSITION (HEAD3) | G33: =VLOOKUP(E33,'2. T-Memory Map'!$D$5:$E$1004,2,FALSE) -> T4245 | H33: =VLOOKUP(G33,'3. M-Memory Map'!$C$4:$D$503,2,FALSE) -> M4175 | M33: ='1. IO 작성 Map'!M32 -> 26 | N33: ='1. IO 작성 Map'!N32 -> Y1119 | O33: ='1. IO 작성 Map'!O32 -> VOICE BUZZER CH2 ON | P33: =VLOOKUP(N33,'3. M-Memory Map'!$C$508:$D$1007,2,FALSE) -> #N/A | S33: B RATE | T33: ='1. IO 작성 Map'!T32 -> 4 | AA33: ='1. IO 작성 Map'!AA32 -> 0 | AB33: ='1. IO 작성 Map'!AB32 -> 0 | AC33: ='1. IO 작성 Map'!AC32 -> 0 | AD33: ='1. IO 작성 Map'!AD32:AE32 -> 0 | AF33: ='1. IO 작성 Map'!AF32 -> 0 | AG33: ='1. IO 작성 Map'!AG32 -> 0 | AH33: ='1. IO 작성 Map'!AH32 -> 0
D34: ='1. IO 작성 Map'!D33 -> 27 | E34: ='1. IO 작성 Map'!E33 -> X101A | F34: ='1. IO 작성 Map'!F33 -> Y3-UNLOADING POSITION (HEAD4) | G34: =VLOOKUP(E34,'2. T-Memory Map'!$D$5:$E$1004,2,FALSE) -> T4246 | H34: =VLOOKUP(G34,'3. M-Memory Map'!$C$4:$D$503,2,FALSE) -> M4176 | M34: ='1. IO 작성 Map'!M33 -> 27 | N34: ='1. IO 작성 Map'!N33 -> Y111A | O34: ='1. IO 작성 Map'!O33 -> VOICE BUZZER CH3 ON | P34: =VLOOKUP(N34,'3. M-Memory Map'!$C$508:$D$1007,2,FALSE) -> #N/A | S34: MODE | T34: ='1. IO 작성 Map'!T33 -> 3
D35: ='1. IO 작성 Map'!D34 -> 28 | E35: ='1. IO 작성 Map'!E34 -> X101B | F35: ='1. IO 작성 Map'!F34 -> X4-UNLOADING POSITION (PROBE GANTRY 1) | G35: =VLOOKUP(E35,'2. T-Memory Map'!$D$5:$E$1004,2,FALSE) -> T4340 | H35: =VLOOKUP(G35,'3. M-Memory Map'!$C$4:$D$503,2,FALSE) -> M4490 | M35: ='1. IO 작성 Map'!M34 -> 28 | N35: ='1. IO 작성 Map'!N34 -> Y111B | O35: ='1. IO 작성 Map'!O34 -> VOICE BUZZER CH4 ON | P35: =VLOOKUP(N35,'3. M-Memory Map'!$C$508:$D$1007,2,FALSE) -> #N/A | S35: ANALOG INPUT | AA35: B RATE | AB35: 4
D36: ='1. IO 작성 Map'!D35 -> 29 | E36: ='1. IO 작성 Map'!E35 -> X101C | F36: ='1. IO 작성 Map'!F35 -> X6-UNLOADING POSITION (PROBE GANTRY 2) | G36: =VLOOKUP(E36,'2. T-Memory Map'!$D$5:$E$1004,2,FALSE) -> T4341 | H36: =VLOOKUP(G36,'3. M-Memory Map'!$C$4:$D$503,2,FALSE) -> M4491 | M36: ='1. IO 작성 Map'!M35 -> 29 | N36: ='1. IO 작성 Map'!N35 -> Y111C | O36: ='1. IO 작성 Map'!O35 -> VOICE BUZZER CH5 ON (RESERVED) | P36: =VLOOKUP(N36,'3. M-Memory Map'!$C$508:$D$1007,2,FALSE) -> #N/A | AA36: MODE | AB36: 1
D37: ='1. IO 작성 Map'!D36 -> 30 | E37: ='1. IO 작성 Map'!E36 -> X101D | F37: ='1. IO 작성 Map'!F36 -> X8-UNLOADING POSITION (PROBE GANTRY 3) | G37: =VLOOKUP(E37,'2. T-Memory Map'!$D$5:$E$1004,2,FALSE) -> T4342 | H37: =VLOOKUP(G37,'3. M-Memory Map'!$C$4:$D$503,2,FALSE) -> M4492 | M37: ='1. IO 작성 Map'!M36 -> 30 | N37: ='1. IO 작성 Map'!N36 -> Y111D | O37: ='1. IO 작성 Map'!O36 -> VOICE BUZZER CH6 ON (RESERVED) | P37: =VLOOKUP(N37,'3. M-Memory Map'!$C$508:$D$1007,2,FALSE) -> #N/A | S37: STATION No. | T37: Part No. | U37: 번호 | V37: I/O | W37: Description | AA37: SW ON↑ | AB37: 1, 3, 5
D38: ='1. IO 작성 Map'!D37 -> 31 | E38: ='1. IO 작성 Map'!E37 -> X101E | F38: ='1. IO 작성 Map'!F37 -> X10-UNLOADING POSITION (PROBE GANTRY 4) | G38: =VLOOKUP(E38,'2. T-Memory Map'!$D$5:$E$1004,2,FALSE) -> T4343 | H38: =VLOOKUP(G38,'3. M-Memory Map'!$C$4:$D$503,2,FALSE) -> M4493 | M38: ='1. IO 작성 Map'!M37 -> 31 | N38: ='1. IO 작성 Map'!N37 -> Y111E | O38: ='1. IO 작성 Map'!O37 -> VOICE BUZZER CH7 ON (RESERVED) | P38: =VLOOKUP(N38,'3. M-Memory Map'!$C$508:$D$1007,2,FALSE) -> #N/A | S38: ='1. IO 작성 Map'!S37:X37 -> HI-BOX | AA38: RS-232 COMM.
D39: ='1. IO 작성 Map'!D38 -> 32 | E39: ='1. IO 작성 Map'!E38 -> X101F | F39: ='1. IO 작성 Map'!F38 -> X12-UNLOADING POSITION (PROBE GANTRY 5) | G39: =VLOOKUP(E39,'2. T-Memory Map'!$D$5:$E$1004,2,FALSE) -> T4344 | H39: =VLOOKUP(G39,'3. M-Memory Map'!$C$4:$D$503,2,FALSE) -> M4494 | M39: ='1. IO 작성 Map'!M38 -> 32 | N39: ='1. IO 작성 Map'!N38 -> Y111F | O39: ='1. IO 작성 Map'!O38 -> VOICE BUZZER CH8 ON (RESERVED) | P39: =VLOOKUP(N39,'3. M-Memory Map'!$C$508:$D$1007,2,FALSE) -> #N/A | S39: ='1. IO 작성 Map'!S38:S45 -> 0 | T39: ='1. IO 작성 Map'!T38:T45 -> 0 | U39: ='1. IO 작성 Map'!U38 -> 1 | V39: ='1. IO 작성 Map'!V38 -> CH1 | W39: ='1. IO 작성 Map'!W38 -> ZERO POSITION_4 | X39: ='1. IO 작성 Map'!X38 -> 0 | Y39: ='1. IO 작성 Map'!Y38 -> ISE20B | AA39: STATION No. | AB39: Part No. | AC39: 번호 | AF39: Description
B40: ='1. IO 작성 Map'!B39:F39 -> EQ | K40: ='1. IO 작성 Map'!K39:Q39 -> PROFILE | U40: ='1. IO 작성 Map'!U39 -> 2 | V40: ='1. IO 작성 Map'!V39 -> CH2 | W40: ='1. IO 작성 Map'!W39 -> ZERO POSITION_5 | X40: ='1. IO 작성 Map'!X39 -> 0 | Y40: ='1. IO 작성 Map'!Y39 -> ISE20B
...

Sheet F-Alarm Memory Map
B2: F-Alarm Memory Map | G2: F1 ~ F50 | H2: System Alarm | I2: 50
G3: F51 ~ F100 | H3: System Warning | I3: 50
B4: No | D4: Address | E4: Comment | G4: F101 ~ F600 | H4: EQ Alarm | I4: 500
B5: System Alarm | G5: F601 ~ F700 | H5: EQ Warning | I5: 100
B6: 1 | C6: EMO | D6: F1 | E6: EMO Push 01 Alarm | G6: F701 ~ F900 | H6: PACC Alarm | I6: 200
B7: 2 | D7: F2 | E7: EMO Push 02 Alarm | G7: F901 ~ F1000 | H7: PACC Warning | I7: 100
B8: 3 | D8: F3 | E8: EMO Push 03 Alarm | G8: F1001 ~ F1500 | H8: CIM Error | I8: 500
B9: 4 | D9: F4 | E9: EMO Push 04 Alarm
B10: 5 | D10: F5 | E10: EMO Push 05 Alarm
B11: 6 | D11: F6 | E11: EMO Push 06 Alarm
B12: 7 | D12: F7 | E12: EMO Push 07 Alarm
B13: 8 | D13: F8 | E13: EMO Push 08 Alarm
B14: 9 | D14: F9 | E14: EMO Push 09 Alarm
B15: 10 | D15: F10 | E15: EMO Push 10 Alarm
B16: 11 | C16: EMO | D16: F11 | E16: EMO Push 11 Alarm
B17: 12 | D17: F12 | E17: EMO Push 12 Alarm
B18: 13 | D18: F13 | E18: EMO Push 13 Alarm
B19: 14 | D19: F14 | E19: EMO Push 14 Alarm
B20: 15 | D20: F15 | E20: EMO Push 15 Alarm
B21: 16 | D21: F16 | E21: EMO Push 16 Alarm
B22: 17 | D22: F17
B23: 18 | D23: F18
B24: 19 | D24: F19
B25: 20 | D25: F20
B26: 21 | C26: Purifier | D26: F21 | E26: Purifier Alarm
B27: 22 | D27: F22
B28: 23 | D28: F23
B29: 24 | D29: F24
B30: 25 | D30: F25
B31: 26 | D31: F26
B32: 27 | D32: F27
B33: 28 | D33: F28
B34: 29 | D34: F29
B35: 30 | D35: F30
B36: 31 | C36: SPARE | D36: F31
B37: 32 | D37: F32
B38: 33 | D38: F33
B39: 34 | D39: F34
B40: 35 | D40: F35
B41: 36 | D41: F36
...

Sheet FDC
B2: EQ
B3: Group | C3: SVID | D3: Parameter Name | E3: PLC > SW | F3: SW > PLC | G3: CIM > HOST
B4: Pressure (Main 1차) | D4: CDA 01 | E4: D11500
D5: CDA 02 | E5: D11502
D6: CDA 03 | E6: D11504
D7: FIXTURE 01 | E7: D11506
D8: FIXTURE 02 | E8: D11508
D9: ISOLATOR 01 | E9: D11510
D10: ISOLATOR 02 | E10: D11512
D11: SHUTTER | E11: D11514
E12: D11516
E13: D11518
D14: PROBE MODULE_1 | E14: D11520
D15: PROBE MODULE_2 | E15: D11522
D16: PROBE MODULE_3 | E16: D11524
D17: PROBE MODULE_4 | E17: D11526
D18: PROBE MODULE_5 | E18: D11528
D19: ZERO POSITION_1 | E19: D11530
D20: ZERO POSITION_2 | E20: D11532
D21: ZERO POSITION_3 | E21: D11534
D22: ZERO POSITION_4 | E22: D11536
D23: ZERO POSITION_5 | E23: D11538
D24: VACUUM 01 | E24: D11540
D25: VACUUM 02 | E25: D11542
E26: D11544
E27: D11546
E28: D11548
E29: D11550
E30: D11552
E31: D11554
E32: D11556
E33: D11558
D34: PLATE BLOW_VACUUM 01 | E34: D11560
E35: D11562
E36: D11564
E37: D11566
E38: D11568
E39: D11570
E40: D11572
E41: D11574
...

Sheet PC CIM (M400)
B2: M400번지 Memory Map
B3: No | D3: Address | E3: Comment
B4: INPUT (M400 ~ M499)
B5: 1 | C5: Door | D5: M400 | E5: Door 01 Open
B6: 2 | D6: M401 | E6: Door 02 Open
B7: 3 | D7: M402 | E7: Door 03 Open
B8: 4 | D8: M403
B9: 5 | D9: M404
B10: 6 | D10: M405
B11: 7 | D11: M406
B12: 8 | D12: M407
B13: 9 | D13: M408
B14: 10 | D14: M409
B15: 11 | C15: EMO | D15: M410 | E15: EMO 01 Push
B16: 12 | D16: M411 | E16: EMO 02 Push
B17: 13 | D17: M412 | E17: EMO 03 Push
B18: 14 | D18: M413 | E18: EMO 04 Push
B19: 15 | D19: M414 | E19: EMO 05 Push
B20: 16 | D20: M415
B21: 17 | D21: M416
B22: 18 | D22: M417
B23: 19 | D23: M418
B24: 20 | D24: M419
B25: 21 | C25: Glass Check | D25: M420 | E25: Glass Check
B26: 22 | D26: M421
B27: 23 | D27: M422
B28: 24 | D28: M423
B29: 25 | D29: M424
B30: 26 | C30: Loader Arm Detect | D30: M425 | E30: Loader Arm Detect 01
B31: 27 | D31: M426
B32: 28 | D32: M427
B33: 29 | D33: M428
B34: 30 | D34: M429
B35: 31 | C35: Shutter Up / Down | D35: M430 | E35: EQ Shutter Close
B36: 32 | D36: M431 | E36: EQ Shutter Open
B37: 33 | D37: M432
B38: 34 | D38: M433
B39: 35 | D39: M434
B40: 36 | C40: Lift Pin / LP | D40: M435 | E40: Lift Pin Up
B41: 37 | D41: M436 | E41: Lift Pin Down
...
